Workbook

Sheet หน้าสูตร干线到车 รถถึงสายรอง  KKN
B2: 2026.05.11 | E2: KKN 转运中心干线到车统计表 บันทึกข้อมูลรถถึงสายรอง
B3: 序号 | C3: 任务状态 | D3: 任务单 | E3: 路线 | F3: 车辆类型 | G3: 车牌号 | H3: 司机名称 | I3: 供应商 | J3: 计划到车时间 | K3: 实际到车时间 เวลารถถึง | L3: เวลาที่ควรลง (ไม่เกิน2hr.) | M3: 解车时间 | N3: 卸车开始时间 | O3: สถานะความผิดปกติ | P3: 卸车结束时间 | Q3: 卸车状态 | R3: 备注 | S3: สาเหตุ | T3: ระยะเวลาลงงาน (นาที)
B4: NO. | C4: สถานะ | D4: เลขมอบหมายงาน | E4: รอบรถ | F4: ประเภทรถ | G4: ทะเบียน | H4: ชื่อคนขับ | I4: ซัพพลายเออร์ | J4: คาดการณ์ เวลารถถึง | M4: เวลาเปิดตู้รถถึง | N4: เวลาเริ่มลงพัสดุ | P4: เวลาสิ้นสุดลงพัสดุ | Q4: สถานะลงของ | R4: หมายเหตุ
B5: 1 | C5: =_xlfn.XLOOKUP(D:D,'DATA รถถึงเส้นรอง KKN'!A:A,'DATA รถถึงเส้นรอง KKN'!B:B) -> #N/A | D5: =_xlfn.XLOOKUP(E5,'DATA รถถึงเส้นรอง KKN'!C:C,'DATA รถถึงเส้นรอง KKN'!A:A) -> #N/A | E5: {=INDEX('DATA รถถึงเส้นรอง KKN'!C:C,ROW()-3)} -> 0 | F5: =_xlfn.XLOOKUP(E5,'DATA รถถึงเส้นรอง KKN'!C:C,'DATA รถถึงเส้นรอง KKN'!O:O) -> #N/A | G5: =_xlfn.XLOOKUP(E5,'DATA รถถึงเส้นรอง KKN'!C:C,'DATA รถถึงเส้นรอง KKN'!L:L) -> #N/A | H5: =_xlfn.XLOOKUP(E5,#REF!,#REF!) -> #REF! | I5: =_xlfn.XLOOKUP(E5,#REF!,#REF!) -> #REF! | J5: =_xlfn.XLOOKUP(E5,'DATA รถถึงเส้นรอง KKN'!C:C,'DATA รถถึงเส้นรอง KKN'!AP:AP) -> #N/A | K5: =_xlfn.XLOOKUP(E5,'DATA รถถึงเส้นรอง KKN'!C:C,'DATA รถถึงเส้นรอง KKN'!AV:AV) -> #N/A | L5: =M5+TIME(2,0,0) -> #N/A | M5: =_xlfn.XLOOKUP(E5,'DATA รถถึงเส้นรอง KKN'!C:C,'DATA รถถึงเส้นรอง KKN'!AW:AW) -> #N/A | N5: =_xlfn.XLOOKUP(E5,'DATA รถถึงเส้นรอง KKN'!C:C,'DATA รถถึงเส้นรอง KKN'!AY:AY) -> #N/A | O5: =IF(OR(N5=0,L5=0,N5="",L5=""),"ข้อมูลไม่ครบ",IF(TEXT(N5,"hh:mm:ss")>TEXT(L5,"hh:mm:ss"),"เกินเวลาลงพัสดุ","อยู่ในเวลาที่ควรลง")) -> #N/A | P5: =_xlfn.XLOOKUP(E5,'DATA รถถึงเส้นรอง KKN'!C:C,'DATA รถถึงเส้นรอง KKN'!AZ:AZ) -> #N/A | Q5: =IFERROR(IF(AND(P5<>"",P5<>0),"卸完货 ลงพัสดุเสร็จ",IF(AND(N5<>"",N5<>0),"正在卸货 กำลังลงพัสดุ",IF(AND(M5<>"",M5<>0),"等待卸货 รอลงพัสดุ",IF(OR(AND(J5<>"",J5<>0),AND(K5<>"",K5<>0)),"在途 รถยังไม่ถึง","")))),"") | T5: =INT((V5-W5)*1440) -> #N/A | V5: =RIGHT(P5,8) -> #N/A | W5: =RIGHT(N5,8) -> #N/A | X5: =MOD(V5-W5,1) -> #N/A
B6: 2 | C6: =_xlfn.XLOOKUP(D:D,'DATA รถถึงเส้นรอง KKN'!A:A,'DATA รถถึงเส้นรอง KKN'!B:B) -> #N/A | D6: =_xlfn.XLOOKUP(E6,'DATA รถถึงเส้นรอง KKN'!C:C,'DATA รถถึงเส้นรอง KKN'!A:A) -> #N/A | E6: {=INDEX('DATA รถถึงเส้นรอง KKN'!C:C,ROW()-3)} -> 0 | F6: =_xlfn.XLOOKUP(E6,'DATA รถถึงเส้นรอง KKN'!C:C,'DATA รถถึงเส้นรอง KKN'!O:O) -> #N/A | G6: =_xlfn.XLOOKUP(E6,'DATA รถถึงเส้นรอง KKN'!C:C,'DATA รถถึงเส้นรอง KKN'!L:L) -> #N/A | H6: =_xlfn.XLOOKUP(E6,#REF!,#REF!) -> #REF! | I6: =_xlfn.XLOOKUP(E6,#REF!,#REF!) -> #REF! | J6: =_xlfn.XLOOKUP(E6,'DATA รถถึงเส้นรอง KKN'!C:C,'DATA รถถึงเส้นรอง KKN'!AP:AP) -> #N/A | K6: =_xlfn.XLOOKUP(E6,'DATA รถถึงเส้นรอง KKN'!C:C,'DATA รถถึงเส้นรอง KKN'!AV:AV) -> #N/A | L6: =M6+TIME(2,0,0) -> #N/A | M6: =_xlfn.XLOOKUP(E6,'DATA รถถึงเส้นรอง KKN'!C:C,'DATA รถถึงเส้นรอง KKN'!AW:AW) -> #N/A | N6: =_xlfn.XLOOKUP(E6,'DATA รถถึงเส้นรอง KKN'!C:C,'DATA รถถึงเส้นรอง KKN'!AY:AY) -> #N/A | O6: =IF(OR(N6=0,L6=0,N6="",L6=""),"ข้อมูลไม่ครบ",IF(TEXT(N6,"hh:mm:ss")>TEXT(L6,"hh:mm:ss"),"เกินเวลาลงพัสดุ","อยู่ในเวลาที่ควรลง")) -> #N/A | P6: =_xlfn.XLOOKUP(E6,'DATA รถถึงเส้นรอง KKN'!C:C,'DATA รถถึงเส้นรอง KKN'!AZ:AZ) -> #N/A | Q6: =IFERROR(IF(AND(P6<>"",P6<>0),"卸完货 ลงพัสดุเสร็จ",IF(AND(N6<>"",N6<>0),"正在卸货 กำลังลงพัสดุ",IF(AND(M6<>"",M6<>0),"等待卸货 รอลงพัสดุ",IF(OR(AND(J6<>"",J6<>0),AND(K6<>"",K6<>0)),"在途 รถยังไม่ถึง","")))),"") | T6: =INT((V6-W6)*1440) -> #N/A | V6: =RIGHT(P6,8) -> #N/A | W6: =RIGHT(N6,8) -> #N/A | X6: =MOD(V6-W6,1) -> #N/A
B7: 3 | C7: =_xlfn.XLOOKUP(D:D,'DATA รถถึงเส้นรอง KKN'!A:A,'DATA รถถึงเส้นรอง KKN'!B:B) -> #N/A | D7: =_xlfn.XLOOKUP(E7,'DATA รถถึงเส้นรอง KKN'!C:C,'DATA รถถึงเส้นรอง KKN'!A:A) -> #N/A | E7: {=INDEX('DATA รถถึงเส้นรอง KKN'!C:C,ROW()-3)} -> 0 | F7: =_xlfn.XLOOKUP(E7,'DATA รถถึงเส้นรอง KKN'!C:C,'DATA รถถึงเส้นรอง KKN'!O:O) -> #N/A | G7: =_xlfn.XLOOKUP(E7,'DATA รถถึงเส้นรอง KKN'!C:C,'DATA รถถึงเส้นรอง KKN'!L:L) -> #N/A | H7: =_xlfn.XLOOKUP(E7,#REF!,#REF!) -> #REF! | I7: =_xlfn.XLOOKUP(E7,#REF!,#REF!) -> #REF! | J7: =_xlfn.XLOOKUP(E7,'DATA รถถึงเส้นรอง KKN'!C:C,'DATA รถถึงเส้นรอง KKN'!AP:AP) -> #N/A | K7: =_xlfn.XLOOKUP(E7,'DATA รถถึงเส้นรอง KKN'!C:C,'DATA รถถึงเส้นรอง KKN'!AV:AV) -> #N/A | L7: =M7+TIME(2,0,0) -> #N/A | M7: =_xlfn.XLOOKUP(E7,'DATA รถถึงเส้นรอง KKN'!C:C,'DATA รถถึงเส้นรอง KKN'!AW:AW) -> #N/A | N7: =_xlfn.XLOOKUP(E7,'DATA รถถึงเส้นรอง KKN'!C:C,'DATA รถถึงเส้นรอง KKN'!AY:AY) -> #N/A | O7: =IF(OR(N7=0,L7=0,N7="",L7=""),"ข้อมูลไม่ครบ",IF(TEXT(N7,"hh:mm:ss")>TEXT(L7,"hh:mm:ss"),"เกินเวลาลงพัสดุ","อยู่ในเวลาที่ควรลง")) -> #N/A | P7: =_xlfn.XLOOKUP(E7,'DATA รถถึงเส้นรอง KKN'!C:C,'DATA รถถึงเส้นรอง KKN'!AZ:AZ) -> #N/A | Q7: =IFERROR(IF(AND(P7<>"",P7<>0),"卸完货 ลงพัสดุเสร็จ",IF(AND(N7<>"",N7<>0),"正在卸货 กำลังลงพัสดุ",IF(AND(M7<>"",M7<>0),"等待卸货 รอลงพัสดุ",IF(OR(AND(J7<>"",J7<>0),AND(K7<>"",K7<>0)),"在途 รถยังไม่ถึง","")))),"") | T7: =INT((V7-W7)*1440) -> #N/A | V7: =RIGHT(P7,8) -> #N/A | W7: =RIGHT(N7,8) -> #N/A | X7: =MOD(V7-W7,1) -> #N/A
B8: 4 | C8: =_xlfn.XLOOKUP(D:D,'DATA รถถึงเส้นรอง KKN'!A:A,'DATA รถถึงเส้นรอง KKN'!B:B) -> #N/A | D8: =_xlfn.XLOOKUP(E8,'DATA รถถึงเส้นรอง KKN'!C:C,'DATA รถถึงเส้นรอง KKN'!A:A) -> #N/A | E8: {=INDEX('DATA รถถึงเส้นรอง KKN'!C:C,ROW()-3)} -> 0 | F8: =_xlfn.XLOOKUP(E8,'DATA รถถึงเส้นรอง KKN'!C:C,'DATA รถถึงเส้นรอง KKN'!O:O) -> #N/A | G8: =_xlfn.XLOOKUP(E8,'DATA รถถึงเส้นรอง KKN'!C:C,'DATA รถถึงเส้นรอง KKN'!L:L) -> #N/A | H8: =_xlfn.XLOOKUP(E8,#REF!,#REF!) -> #REF! | I8: =_xlfn.XLOOKUP(E8,#REF!,#REF!) -> #REF! | J8: =_xlfn.XLOOKUP(E8,'DATA รถถึงเส้นรอง KKN'!C:C,'DATA รถถึงเส้นรอง KKN'!AP:AP) -> #N/A | K8: =_xlfn.XLOOKUP(E8,'DATA รถถึงเส้นรอง KKN'!C:C,'DATA รถถึงเส้นรอง KKN'!AV:AV) -> #N/A | L8: =M8+TIME(2,0,0) -> #N/A | M8: =_xlfn.XLOOKUP(E8,'DATA รถถึงเส้นรอง KKN'!C:C,'DATA รถถึงเส้นรอง KKN'!AW:AW) -> #N/A | N8: =_xlfn.XLOOKUP(E8,'DATA รถถึงเส้นรอง KKN'!C:C,'DATA รถถึงเส้นรอง KKN'!AY:AY) -> #N/A | O8: =IF(OR(N8=0,L8=0,N8="",L8=""),"ข้อมูลไม่ครบ",IF(TEXT(N8,"hh:mm:ss")>TEXT(L8,"hh:mm:ss"),"เกินเวลาลงพัสดุ","อยู่ในเวลาที่ควรลง")) -> #N/A | P8: =_xlfn.XLOOKUP(E8,'DATA รถถึงเส้นรอง KKN'!C:C,'DATA รถถึงเส้นรอง KKN'!AZ:AZ) -> #N/A | Q8: =IFERROR(IF(AND(P8<>"",P8<>0),"卸完货 ลงพัสดุเสร็จ",IF(AND(N8<>"",N8<>0),"正在卸货 กำลังลงพัสดุ",IF(AND(M8<>"",M8<>0),"等待卸货 รอลงพัสดุ",IF(OR(AND(J8<>"",J8<>0),AND(K8<>"",K8<>0)),"在途 รถยังไม่ถึง","")))),"") | T8: =INT((V8-W8)*1440) -> #N/A | V8: =RIGHT(P8,8) -> #N/A | W8: =RIGHT(N8,8) -> #N/A | X8: =MOD(V8-W8,1) -> #N/A
B9: 5 | C9: =_xlfn.XLOOKUP(D:D,'DATA รถถึงเส้นรอง KKN'!A:A,'DATA รถถึงเส้นรอง KKN'!B:B) -> #N/A | D9: =_xlfn.XLOOKUP(E9,'DATA รถถึงเส้นรอง KKN'!C:C,'DATA รถถึงเส้นรอง KKN'!A:A) -> #N/A | E9: {=INDEX('DATA รถถึงเส้นรอง KKN'!C:C,ROW()-3)} -> 0 | F9: =_xlfn.XLOOKUP(E9,'DATA รถถึงเส้นรอง KKN'!C:C,'DATA รถถึงเส้นรอง KKN'!O:O) -> #N/A | G9: =_xlfn.XLOOKUP(E9,'DATA รถถึงเส้นรอง KKN'!C:C,'DATA รถถึงเส้นรอง KKN'!L:L) -> #N/A | H9: =_xlfn.XLOOKUP(E9,#REF!,#REF!) -> #REF! | I9: =_xlfn.XLOOKUP(E9,#REF!,#REF!) -> #REF! | J9: =_xlfn.XLOOKUP(E9,'DATA รถถึงเส้นรอง KKN'!C:C,'DATA รถถึงเส้นรอง KKN'!AP:AP) -> #N/A | K9: =_xlfn.XLOOKUP(E9,'DATA รถถึงเส้นรอง KKN'!C:C,'DATA รถถึงเส้นรอง KKN'!AV:AV) -> #N/A | L9: =M9+TIME(2,0,0) -> #N/A | M9: =_xlfn.XLOOKUP(E9,'DATA รถถึงเส้นรอง KKN'!C:C,'DATA รถถึงเส้นรอง KKN'!AW:AW) -> #N/A | N9: =_xlfn.XLOOKUP(E9,'DATA รถถึงเส้นรอง KKN'!C:C,'DATA รถถึงเส้นรอง KKN'!AY:AY) -> #N/A | O9: =IF(OR(N9=0,L9=0,N9="",L9=""),"ข้อมูลไม่ครบ",IF(TEXT(N9,"hh:mm:ss")>TEXT(L9,"hh:mm:ss"),"เกินเวลาลงพัสดุ","อยู่ในเวลาที่ควรลง")) -> #N/A | P9: =_xlfn.XLOOKUP(E9,'DATA รถถึงเส้นรอง KKN'!C:C,'DATA รถถึงเส้นรอง KKN'!AZ:AZ) -> #N/A | Q9: =IFERROR(IF(AND(P9<>"",P9<>0),"卸完货 ลงพัสดุเสร็จ",IF(AND(N9<>"",N9<>0),"正在卸货 กำลังลงพัสดุ",IF(AND(M9<>"",M9<>0),"等待卸货 รอลงพัสดุ",IF(OR(AND(J9<>"",J9<>0),AND(K9<>"",K9<>0)),"在途 รถยังไม่ถึง","")))),"") | T9: =INT((V9-W9)*1440) -> #N/A | V9: =RIGHT(P9,8) -> #N/A | W9: =RIGHT(N9,8) -> #N/A | X9: =MOD(V9-W9,1) -> #N/A
B10: 6 | C10: =_xlfn.XLOOKUP(D:D,'DATA รถถึงเส้นรอง KKN'!A:A,'DATA รถถึงเส้นรอง KKN'!B:B) -> #N/A | D10: =_xlfn.XLOOKUP(E10,'DATA รถถึงเส้นรอง KKN'!C:C,'DATA รถถึงเส้นรอง KKN'!A:A) -> #N/A | E10: {=INDEX('DATA รถถึงเส้นรอง KKN'!C:C,ROW()-3)} -> 0 | F10: =_xlfn.XLOOKUP(E10,'DATA รถถึงเส้นรอง KKN'!C:C,'DATA รถถึงเส้นรอง KKN'!O:O) -> #N/A | G10: =_xlfn.XLOOKUP(E10,'DATA รถถึงเส้นรอง KKN'!C:C,'DATA รถถึงเส้นรอง KKN'!L:L) -> #N/A | H10: =_xlfn.XLOOKUP(E10,#REF!,#REF!) -> #REF! | I10: =_xlfn.XLOOKUP(E10,#REF!,#REF!) -> #REF! | J10: =_xlfn.XLOOKUP(E10,'DATA รถถึงเส้นรอง KKN'!C:C,'DATA รถถึงเส้นรอง KKN'!AP:AP) -> #N/A | K10: =_xlfn.XLOOKUP(E10,'DATA รถถึงเส้นรอง KKN'!C:C,'DATA รถถึงเส้นรอง KKN'!AV:AV) -> #N/A | L10: =M10+TIME(2,0,0) -> #N/A | M10: =_xlfn.XLOOKUP(E10,'DATA รถถึงเส้นรอง KKN'!C:C,'DATA รถถึงเส้นรอง KKN'!AW:AW) -> #N/A | N10: =_xlfn.XLOOKUP(E10,'DATA รถถึงเส้นรอง KKN'!C:C,'DATA รถถึงเส้นรอง KKN'!AY:AY) -> #N/A | O10: =IF(OR(N10=0,L10=0,N10="",L10=""),"ข้อมูลไม่ครบ",IF(TEXT(N10,"hh:mm:ss")>TEXT(L10,"hh:mm:ss"),"เกินเวลาลงพัสดุ","อยู่ในเวลาที่ควรลง")) -> #N/A | P10: =_xlfn.XLOOKUP(E10,'DATA รถถึงเส้นรอง KKN'!C:C,'DATA รถถึงเส้นรอง KKN'!AZ:AZ) -> #N/A | Q10: =IFERROR(IF(AND(P10<>"",P10<>0),"卸完货 ลงพัสดุเสร็จ",IF(AND(N10<>"",N10<>0),"正在卸货 กำลังลงพัสดุ",IF(AND(M10<>"",M10<>0),"等待卸货 รอลงพัสดุ",IF(OR(AND(J10<>"",J10<>0),AND(K10<>"",K10<>0)),"在途 รถยังไม่ถึง","")))),"") | T10: =INT((V10-W10)*1440) -> #N/A | V10: =RIGHT(P10,8) -> #N/A | W10: =RIGHT(N10,8) -> #N/A | X10: =MOD(V10-W10,1) -> #N/A
B11: 7 | C11: =_xlfn.XLOOKUP(D:D,'DATA รถถึงเส้นรอง KKN'!A:A,'DATA รถถึงเส้นรอง KKN'!B:B) -> #N/A | D11: =_xlfn.XLOOKUP(E11,'DATA รถถึงเส้นรอง KKN'!C:C,'DATA รถถึงเส้นรอง KKN'!A:A) -> #N/A | E11: {=INDEX('DATA รถถึงเส้นรอง KKN'!C:C,ROW()-3)} -> 0 | F11: =_xlfn.XLOOKUP(E11,'DATA รถถึงเส้นรอง KKN'!C:C,'DATA รถถึงเส้นรอง KKN'!O:O) -> #N/A | G11: =_xlfn.XLOOKUP(E11,'DATA รถถึงเส้นรอง KKN'!C:C,'DATA รถถึงเส้นรอง KKN'!L:L) -> #N/A | H11: =_xlfn.XLOOKUP(E11,#REF!,#REF!) -> #REF! | I11: =_xlfn.XLOOKUP(E11,#REF!,#REF!) -> #REF! | J11: =_xlfn.XLOOKUP(E11,'DATA รถถึงเส้นรอง KKN'!C:C,'DATA รถถึงเส้นรอง KKN'!AP:AP) -> #N/A | K11: =_xlfn.XLOOKUP(E11,'DATA รถถึงเส้นรอง KKN'!C:C,'DATA รถถึงเส้นรอง KKN'!AV:AV) -> #N/A | L11: =M11+TIME(2,0,0) -> #N/A | M11: =_xlfn.XLOOKUP(E11,'DATA รถถึงเส้นรอง KKN'!C:C,'DATA รถถึงเส้นรอง KKN'!AW:AW) -> #N/A | N11: =_xlfn.XLOOKUP(E11,'DATA รถถึงเส้นรอง KKN'!C:C,'DATA รถถึงเส้นรอง KKN'!AY:AY) -> #N/A | O11: =IF(OR(N11=0,L11=0,N11="",L11=""),"ข้อมูลไม่ครบ",IF(TEXT(N11,"hh:mm:ss")>TEXT(L11,"hh:mm:ss"),"เกินเวลาลงพัสดุ","อยู่ในเวลาที่ควรลง")) -> #N/A | P11: =_xlfn.XLOOKUP(E11,'DATA รถถึงเส้นรอง KKN'!C:C,'DATA รถถึงเส้นรอง KKN'!AZ:AZ) -> #N/A | Q11: =IFERROR(IF(AND(P11<>"",P11<>0),"卸完货 ลงพัสดุเสร็จ",IF(AND(N11<>"",N11<>0),"正在卸货 กำลังลงพัสดุ",IF(AND(M11<>"",M11<>0),"等待卸货 รอลงพัสดุ",IF(OR(AND(J11<>"",J11<>0),AND(K11<>"",K11<>0)),"在途 รถยังไม่ถึง","")))),"") | T11: =INT((V11-W11)*1440) -> #N/A | V11: =RIGHT(P11,8) -> #N/A | W11: =RIGHT(N11,8) -> #N/A | X11: =MOD(V11-W11,1) -> #N/A
B12: 8 | C12: =_xlfn.XLOOKUP(D:D,'DATA รถถึงเส้นรอง KKN'!A:A,'DATA รถถึงเส้นรอง KKN'!B:B) -> #N/A | D12: =_xlfn.XLOOKUP(E12,'DATA รถถึงเส้นรอง KKN'!C:C,'DATA รถถึงเส้นรอง KKN'!A:A) -> #N/A | E12: {=INDEX('DATA รถถึงเส้นรอง KKN'!C:C,ROW()-3)} -> 0 | F12: =_xlfn.XLOOKUP(E12,'DATA รถถึงเส้นรอง KKN'!C:C,'DATA รถถึงเส้นรอง KKN'!O:O) -> #N/A | G12: =_xlfn.XLOOKUP(E12,'DATA รถถึงเส้นรอง KKN'!C:C,'DATA รถถึงเส้นรอง KKN'!L:L) -> #N/A | H12: =_xlfn.XLOOKUP(E12,#REF!,#REF!) -> #REF! | I12: =_xlfn.XLOOKUP(E12,#REF!,#REF!) -> #REF! | J12: =_xlfn.XLOOKUP(E12,'DATA รถถึงเส้นรอง KKN'!C:C,'DATA รถถึงเส้นรอง KKN'!AP:AP) -> #N/A | K12: =_xlfn.XLOOKUP(E12,'DATA รถถึงเส้นรอง KKN'!C:C,'DATA รถถึงเส้นรอง KKN'!AV:AV) -> #N/A | L12: =M12+TIME(2,0,0) -> #N/A | M12: =_xlfn.XLOOKUP(E12,'DATA รถถึงเส้นรอง KKN'!C:C,'DATA รถถึงเส้นรอง KKN'!AW:AW) -> #N/A | N12: =_xlfn.XLOOKUP(E12,'DATA รถถึงเส้นรอง KKN'!C:C,'DATA รถถึงเส้นรอง KKN'!AY:AY) -> #N/A | O12: =IF(OR(N12=0,L12=0,N12="",L12=""),"ข้อมูลไม่ครบ",IF(TEXT(N12,"hh:mm:ss")>TEXT(L12,"hh:mm:ss"),"เกินเวลาลงพัสดุ","อยู่ในเวลาที่ควรลง")) -> #N/A | P12: =_xlfn.XLOOKUP(E12,'DATA รถถึงเส้นรอง KKN'!C:C,'DATA รถถึงเส้นรอง KKN'!AZ:AZ) -> #N/A | Q12: =IFERROR(IF(AND(P12<>"",P12<>0),"卸完货 ลงพัสดุเสร็จ",IF(AND(N12<>"",N12<>0),"正在卸货 กำลังลงพัสดุ",IF(AND(M12<>"",M12<>0),"等待卸货 รอลงพัสดุ",IF(OR(AND(J12<>"",J12<>0),AND(K12<>"",K12<>0)),"在途 รถยังไม่ถึง","")))),"") | T12: =INT((V12-W12)*1440) -> #N/A | V12: =RIGHT(P12,8) -> #N/A | W12: =RIGHT(N12,8) -> #N/A | X12: =MOD(V12-W12,1) -> #N/A
B13: 9 | C13: =_xlfn.XLOOKUP(D:D,'DATA รถถึงเส้นรอง KKN'!A:A,'DATA รถถึงเส้นรอง KKN'!B:B) -> #N/A | D13: =_xlfn.XLOOKUP(E13,'DATA รถถึงเส้นรอง KKN'!C:C,'DATA รถถึงเส้นรอง KKN'!A:A) -> #N/A | E13: {=INDEX('DATA รถถึงเส้นรอง KKN'!C:C,ROW()-3)} -> 0 | F13: =_xlfn.XLOOKUP(E13,'DATA รถถึงเส้นรอง KKN'!C:C,'DATA รถถึงเส้นรอง KKN'!O:O) -> #N/A | G13: =_xlfn.XLOOKUP(E13,'DATA รถถึงเส้นรอง KKN'!C:C,'DATA รถถึงเส้นรอง KKN'!L:L) -> #N/A | H13: =_xlfn.XLOOKUP(E13,#REF!,#REF!) -> #REF! | I13: =_xlfn.XLOOKUP(E13,#REF!,#REF!) -> #REF! | J13: =_xlfn.XLOOKUP(E13,'DATA รถถึงเส้นรอง KKN'!C:C,'DATA รถถึงเส้นรอง KKN'!AP:AP) -> #N/A | K13: =_xlfn.XLOOKUP(E13,'DATA รถถึงเส้นรอง KKN'!C:C,'DATA รถถึงเส้นรอง KKN'!AV:AV) -> #N/A | L13: =M13+TIME(2,0,0) -> #N/A | M13: =_xlfn.XLOOKUP(E13,'DATA รถถึงเส้นรอง KKN'!C:C,'DATA รถถึงเส้นรอง KKN'!AW:AW) -> #N/A | N13: =_xlfn.XLOOKUP(E13,'DATA รถถึงเส้นรอง KKN'!C:C,'DATA รถถึงเส้นรอง KKN'!AY:AY) -> #N/A | O13: =IF(OR(N13=0,L13=0,N13="",L13=""),"ข้อมูลไม่ครบ",IF(TEXT(N13,"hh:mm:ss")>TEXT(L13,"hh:mm:ss"),"เกินเวลาลงพัสดุ","อยู่ในเวลาที่ควรลง")) -> #N/A | P13: =_xlfn.XLOOKUP(E13,'DATA รถถึงเส้นรอง KKN'!C:C,'DATA รถถึงเส้นรอง KKN'!AZ:AZ) -> #N/A | Q13: =IFERROR(IF(AND(P13<>"",P13<>0),"卸完货 ลงพัสดุเสร็จ",IF(AND(N13<>"",N13<>0),"正在卸货 กำลังลงพัสดุ",IF(AND(M13<>"",M13<>0),"等待卸货 รอลงพัสดุ",IF(OR(AND(J13<>"",J13<>0),AND(K13<>"",K13<>0)),"在途 รถยังไม่ถึง","")))),"") | T13: =INT((V13-W13)*1440) -> #N/A | V13: =RIGHT(P13,8) -> #N/A | W13: =RIGHT(N13,8) -> #N/A | X13: =MOD(V13-W13,1) -> #N/A
B14: 10 | C14: =_xlfn.XLOOKUP(D:D,'DATA รถถึงเส้นรอง KKN'!A:A,'DATA รถถึงเส้นรอง KKN'!B:B) -> #N/A | D14: =_xlfn.XLOOKUP(E14,'DATA รถถึงเส้นรอง KKN'!C:C,'DATA รถถึงเส้นรอง KKN'!A:A) -> #N/A | E14: {=INDEX('DATA รถถึงเส้นรอง KKN'!C:C,ROW()-3)} -> 0 | F14: =_xlfn.XLOOKUP(E14,'DATA รถถึงเส้นรอง KKN'!C:C,'DATA รถถึงเส้นรอง KKN'!O:O) -> #N/A | G14: =_xlfn.XLOOKUP(E14,'DATA รถถึงเส้นรอง KKN'!C:C,'DATA รถถึงเส้นรอง KKN'!L:L) -> #N/A | H14: =_xlfn.XLOOKUP(E14,#REF!,#REF!) -> #REF! | I14: =_xlfn.XLOOKUP(E14,#REF!,#REF!) -> #REF! | J14: =_xlfn.XLOOKUP(E14,'DATA รถถึงเส้นรอง KKN'!C:C,'DATA รถถึงเส้นรอง KKN'!AP:AP) -> #N/A | K14: =_xlfn.XLOOKUP(E14,'DATA รถถึงเส้นรอง KKN'!C:C,'DATA รถถึงเส้นรอง KKN'!AV:AV) -> #N/A | L14: =M14+TIME(2,0,0) -> #N/A | M14: =_xlfn.XLOOKUP(E14,'DATA รถถึงเส้นรอง KKN'!C:C,'DATA รถถึงเส้นรอง KKN'!AW:AW) -> #N/A | N14: =_xlfn.XLOOKUP(E14,'DATA รถถึงเส้นรอง KKN'!C:C,'DATA รถถึงเส้นรอง KKN'!AY:AY) -> #N/A | O14: =IF(OR(N14=0,L14=0,N14="",L14=""),"ข้อมูลไม่ครบ",IF(TEXT(N14,"hh:mm:ss")>TEXT(L14,"hh:mm:ss"),"เกินเวลาลงพัสดุ","อยู่ในเวลาที่ควรลง")) -> #N/A | P14: =_xlfn.XLOOKUP(E14,'DATA รถถึงเส้นรอง KKN'!C:C,'DATA รถถึงเส้นรอง KKN'!AZ:AZ) -> #N/A | Q14: =IFERROR(IF(AND(P14<>"",P14<>0),"卸完货 ลงพัสดุเสร็จ",IF(AND(N14<>"",N14<>0),"正在卸货 กำลังลงพัสดุ",IF(AND(M14<>"",M14<>0),"等待卸货 รอลงพัสดุ",IF(OR(AND(J14<>"",J14<>0),AND(K14<>"",K14<>0)),"在途 รถยังไม่ถึง","")))),"") | T14: =INT((V14-W14)*1440) -> #N/A | V14: =RIGHT(P14,8) -> #N/A | W14: =RIGHT(N14,8) -> #N/A | X14: =MOD(V14-W14,1) -> #N/A
B15: 11 | C15: =_xlfn.XLOOKUP(D:D,'DATA รถถึงเส้นรอง KKN'!A:A,'DATA รถถึงเส้นรอง KKN'!B:B) -> #N/A | D15: =_xlfn.XLOOKUP(E15,'DATA รถถึงเส้นรอง KKN'!C:C,'DATA รถถึงเส้นรอง KKN'!A:A) -> #N/A | E15: {=INDEX('DATA รถถึงเส้นรอง KKN'!C:C,ROW()-3)} -> 0 | F15: =_xlfn.XLOOKUP(E15,'DATA รถถึงเส้นรอง KKN'!C:C,'DATA รถถึงเส้นรอง KKN'!O:O) -> #N/A | G15: =_xlfn.XLOOKUP(E15,'DATA รถถึงเส้นรอง KKN'!C:C,'DATA รถถึงเส้นรอง KKN'!L:L) -> #N/A | H15: =_xlfn.XLOOKUP(E15,#REF!,#REF!) -> #REF! | I15: =_xlfn.XLOOKUP(E15,#REF!,#REF!) -> #REF! | J15: =_xlfn.XLOOKUP(E15,'DATA รถถึงเส้นรอง KKN'!C:C,'DATA รถถึงเส้นรอง KKN'!AP:AP) -> #N/A | K15: =_xlfn.XLOOKUP(E15,'DATA รถถึงเส้นรอง KKN'!C:C,'DATA รถถึงเส้นรอง KKN'!AV:AV) -> #N/A | L15: =M15+TIME(2,0,0) -> #N/A | M15: =_xlfn.XLOOKUP(E15,'DATA รถถึงเส้นรอง KKN'!C:C,'DATA รถถึงเส้นรอง KKN'!AW:AW) -> #N/A | N15: =_xlfn.XLOOKUP(E15,'DATA รถถึงเส้นรอง KKN'!C:C,'DATA รถถึงเส้นรอง KKN'!AY:AY) -> #N/A | O15: =IF(OR(N15=0,L15=0,N15="",L15=""),"ข้อมูลไม่ครบ",IF(TEXT(N15,"hh:mm:ss")>TEXT(L15,"hh:mm:ss"),"เกินเวลาลงพัสดุ","อยู่ในเวลาที่ควรลง")) -> #N/A | P15: =_xlfn.XLOOKUP(E15,'DATA รถถึงเส้นรอง KKN'!C:C,'DATA รถถึงเส้นรอง KKN'!AZ:AZ) -> #N/A | Q15: =IFERROR(IF(AND(P15<>"",P15<>0),"卸完货 ลงพัสดุเสร็จ",IF(AND(N15<>"",N15<>0),"正在卸货 กำลังลงพัสดุ",IF(AND(M15<>"",M15<>0),"等待卸货 รอลงพัสดุ",IF(OR(AND(J15<>"",J15<>0),AND(K15<>"",K15<>0)),"在途 รถยังไม่ถึง","")))),"") | T15: =INT((V15-W15)*1440) -> #N/A | V15: =RIGHT(P15,8) -> #N/A | W15: =RIGHT(N15,8) -> #N/A | X15: =MOD(V15-W15,1) -> #N/A
B16: 12 | C16: =_xlfn.XLOOKUP(D:D,'DATA รถถึงเส้นรอง KKN'!A:A,'DATA รถถึงเส้นรอง KKN'!B:B) -> #N/A | D16: =_xlfn.XLOOKUP(E16,'DATA รถถึงเส้นรอง KKN'!C:C,'DATA รถถึงเส้นรอง KKN'!A:A) -> #N/A | E16: {=INDEX('DATA รถถึงเส้นรอง KKN'!C:C,ROW()-3)} -> 0 | F16: =_xlfn.XLOOKUP(E16,'DATA รถถึงเส้นรอง KKN'!C:C,'DATA รถถึงเส้นรอง KKN'!O:O) -> #N/A | G16: =_xlfn.XLOOKUP(E16,'DATA รถถึงเส้นรอง KKN'!C:C,'DATA รถถึงเส้นรอง KKN'!L:L) -> #N/A | H16: =_xlfn.XLOOKUP(E16,#REF!,#REF!) -> #REF! | I16: =_xlfn.XLOOKUP(E16,#REF!,#REF!) -> #REF! | J16: =_xlfn.XLOOKUP(E16,'DATA รถถึงเส้นรอง KKN'!C:C,'DATA รถถึงเส้นรอง KKN'!AP:AP) -> #N/A | K16: =_xlfn.XLOOKUP(E16,'DATA รถถึงเส้นรอง KKN'!C:C,'DATA รถถึงเส้นรอง KKN'!AV:AV) -> #N/A | L16: =M16+TIME(2,0,0) -> #N/A | M16: =_xlfn.XLOOKUP(E16,'DATA รถถึงเส้นรอง KKN'!C:C,'DATA รถถึงเส้นรอง KKN'!AW:AW) -> #N/A | N16: =_xlfn.XLOOKUP(E16,'DATA รถถึงเส้นรอง KKN'!C:C,'DATA รถถึงเส้นรอง KKN'!AY:AY) -> #N/A | O16: =IF(OR(N16=0,L16=0,N16="",L16=""),"ข้อมูลไม่ครบ",IF(TEXT(N16,"hh:mm:ss")>TEXT(L16,"hh:mm:ss"),"เกินเวลาลงพัสดุ","อยู่ในเวลาที่ควรลง")) -> #N/A | P16: =_xlfn.XLOOKUP(E16,'DATA รถถึงเส้นรอง KKN'!C:C,'DATA รถถึงเส้นรอง KKN'!AZ:AZ) -> #N/A | Q16: =IFERROR(IF(AND(P16<>"",P16<>0),"卸完货 ลงพัสดุเสร็จ",IF(AND(N16<>"",N16<>0),"正在卸货 กำลังลงพัสดุ",IF(AND(M16<>"",M16<>0),"等待卸货 รอลงพัสดุ",IF(OR(AND(J16<>"",J16<>0),AND(K16<>"",K16<>0)),"在途 รถยังไม่ถึง","")))),"") | T16: =INT((V16-W16)*1440) -> #N/A | V16: =RIGHT(P16,8) -> #N/A | W16: =RIGHT(N16,8) -> #N/A | X16: =MOD(V16-W16,1) -> #N/A
... B157: 153 | C157: =_xlfn.XLOOKUP(D:D,'DATA รถถึงเส้นรอง KKN'!A:A,'DATA รถถึงเส้นรอง KKN'!B:B) -> #N/A | D157: =_xlfn.XLOOKUP(E157,'DATA รถถึงเส้นรอง KKN'!C:C,'DATA รถถึงเส้นรอง KKN'!A:A) -> #N/A | E157: {=INDEX('DATA รถถึงเส้นรอง KKN'!C:C,ROW()-3)} -> 0 | F157: =_xlfn.XLOOKUP(E157,'DATA รถถึงเส้นรอง KKN'!C:C,'DATA รถถึงเส้นรอง KKN'!O:O) -> #N/A | G157: =_xlfn.XLOOKUP(E157,'DATA รถถึงเส้นรอง KKN'!C:C,'DATA รถถึงเส้นรอง KKN'!L:L) -> #N/A | H157: =_xlfn.XLOOKUP(E157,#REF!,#REF!) -> #REF! | I157: =_xlfn.XLOOKUP(E157,#REF!,#REF!) -> #REF! | J157: =_xlfn.XLOOKUP(E157,'DATA รถถึงเส้นรอง KKN'!C:C,'DATA รถถึงเส้นรอง KKN'!AP:AP) -> #N/A | K157: =_xlfn.XLOOKUP(E157,'DATA รถถึงเส้นรอง KKN'!C:C,'DATA รถถึงเส้นรอง KKN'!AV:AV) -> #N/A | L157: =M157+TIME(2,0,0) -> #N/A | M157: =_xlfn.XLOOKUP(E157,'DATA รถถึงเส้นรอง KKN'!C:C,'DATA รถถึงเส้นรอง KKN'!AW:AW) -> #N/A | N157: =_xlfn.XLOOKUP(E157,'DATA รถถึงเส้นรอง KKN'!C:C,'DATA รถถึงเส้นรอง KKN'!AY:AY) -> #N/A | O157: =IF(OR(N157=0,L157=0,N157="",L157=""),"ข้อมูลไม่ครบ",IF(TEXT(N157,"hh:mm:ss")>TEXT(L157,"hh:mm:ss"),"เกินเวลาลงพัสดุ","อยู่ในเวลาที่ควรลง")) -> #N/A | P157: =_xlfn.XLOOKUP(E157,'DATA รถถึงเส้นรอง KKN'!C:C,'DATA รถถึงเส้นรอง KKN'!AZ:AZ) -> #N/A | Q157: =IFERROR(IF(AND(P157<>"",P157<>0),"卸完货 ลงพัสดุเสร็จ",IF(AND(N157<>"",N157<>0),"正在卸货 กำลังลงพัสดุ",IF(AND(M157<>"",M157<>0),"等待卸货 รอลงพัสดุ",IF(OR(AND(J157<>"",J157<>0),AND(K157<>"",K157<>0)),"在途 รถยังไม่ถึง","")))),"") | T157: =INT((V157-W157)*1440) -> #N/A | V157: =RIGHT(P157,8) -> #N/A | W157: =RIGHT(N157,8) -> #N/A | X157: =MOD(V157-W157,1) -> #N/A
B158: 154 | C158: =_xlfn.XLOOKUP(D:D,'DATA รถถึงเส้นรอง KKN'!A:A,'DATA รถถึงเส้นรอง KKN'!B:B) -> #N/A | D158: =_xlfn.XLOOKUP(E158,'DATA รถถึงเส้นรอง KKN'!C:C,'DATA รถถึงเส้นรอง KKN'!A:A) -> #N/A | E158: {=INDEX('DATA รถถึงเส้นรอง KKN'!C:C,ROW()-3)} -> 0 | F158: =_xlfn.XLOOKUP(E158,'DATA รถถึงเส้นรอง KKN'!C:C,'DATA รถถึงเส้นรอง KKN'!O:O) -> #N/A | G158: =_xlfn.XLOOKUP(E158,'DATA รถถึงเส้นรอง KKN'!C:C,'DATA รถถึงเส้นรอง KKN'!L:L) -> #N/A | H158: =_xlfn.XLOOKUP(E158,#REF!,#REF!) -> #REF! | I158: =_xlfn.XLOOKUP(E158,#REF!,#REF!) -> #REF! | J158: =_xlfn.XLOOKUP(E158,'DATA รถถึงเส้นรอง KKN'!C:C,'DATA รถถึงเส้นรอง KKN'!AP:AP) -> #N/A | K158: =_xlfn.XLOOKUP(E158,'DATA รถถึงเส้นรอง KKN'!C:C,'DATA รถถึงเส้นรอง KKN'!AV:AV) -> #N/A | L158: =M158+TIME(2,0,0) -> #N/A | M158: =_xlfn.XLOOKUP(E158,'DATA รถถึงเส้นรอง KKN'!C:C,'DATA รถถึงเส้นรอง KKN'!AW:AW) -> #N/A | N158: =_xlfn.XLOOKUP(E158,'DATA รถถึงเส้นรอง KKN'!C:C,'DATA รถถึงเส้นรอง KKN'!AY:AY) -> #N/A | O158: =IF(OR(N158=0,L158=0,N158="",L158=""),"ข้อมูลไม่ครบ",IF(TEXT(N158,"hh:mm:ss")>TEXT(L158,"hh:mm:ss"),"เกินเวลาลงพัสดุ","อยู่ในเวลาที่ควรลง")) -> #N/A | P158: =_xlfn.XLOOKUP(E158,'DATA รถถึงเส้นรอง KKN'!C:C,'DATA รถถึงเส้นรอง KKN'!AZ:AZ) -> #N/A | T158: =INT((V158-W158)*1440) -> #N/A | V158: =RIGHT(P158,8) -> #N/A | W158: =RIGHT(N158,8) -> #N/A | X158: =MOD(V158-W158,1) -> #N/A
B159: 155 | C159: =_xlfn.XLOOKUP(D:D,'DATA รถถึงเส้นรอง KKN'!A:A,'DATA รถถึงเส้นรอง KKN'!B:B) -> #N/A | D159: =_xlfn.XLOOKUP(E159,'DATA รถถึงเส้นรอง KKN'!C:C,'DATA รถถึงเส้นรอง KKN'!A:A) -> #N/A | E159: {=INDEX('DATA รถถึงเส้นรอง KKN'!C:C,ROW()-3)} -> 0 | F159: =_xlfn.XLOOKUP(E159,'DATA รถถึงเส้นรอง KKN'!C:C,'DATA รถถึงเส้นรอง KKN'!O:O) -> #N/A | G159: =_xlfn.XLOOKUP(E159,'DATA รถถึงเส้นรอง KKN'!C:C,'DATA รถถึงเส้นรอง KKN'!L:L) -> #N/A | H159: =_xlfn.XLOOKUP(E159,#REF!,#REF!) -> #REF! | I159: =_xlfn.XLOOKUP(E159,#REF!,#REF!) -> #REF! | J159: =_xlfn.XLOOKUP(E159,'DATA รถถึงเส้นรอง KKN'!C:C,'DATA รถถึงเส้นรอง KKN'!AP:AP) -> #N/A | K159: =_xlfn.XLOOKUP(E159,'DATA รถถึงเส้นรอง KKN'!C:C,'DATA รถถึงเส้นรอง KKN'!AV:AV) -> #N/A | L159: =M159+TIME(2,0,0) -> #N/A | M159: =_xlfn.XLOOKUP(E159,'DATA รถถึงเส้นรอง KKN'!C:C,'DATA รถถึงเส้นรอง KKN'!AW:AW) -> #N/A | N159: =_xlfn.XLOOKUP(E159,'DATA รถถึงเส้นรอง KKN'!C:C,'DATA รถถึงเส้นรอง KKN'!AY:AY) -> #N/A | O159: =IF(OR(N159=0,L159=0,N159="",L159=""),"ข้อมูลไม่ครบ",IF(TEXT(N159,"hh:mm:ss")>TEXT(L159,"hh:mm:ss"),"เกินเวลาลงพัสดุ","อยู่ในเวลาที่ควรลง")) -> #N/A | P159: =_xlfn.XLOOKUP(E159,'DATA รถถึงเส้นรอง KKN'!C:C,'DATA รถถึงเส้นรอง KKN'!AZ:AZ) -> #N/A | T159: =INT((V159-W159)*1440) -> #N/A | V159: =RIGHT(P159,8) -> #N/A | W159: =RIGHT(N159,8) -> #N/A | X159: =MOD(V159-W159,1) -> #N/A
B160: 156 | C160: =_xlfn.XLOOKUP(D:D,'DATA รถถึงเส้นรอง KKN'!A:A,'DATA รถถึงเส้นรอง KKN'!B:B) -> #N/A | D160: =_xlfn.XLOOKUP(E160,'DATA รถถึงเส้นรอง KKN'!C:C,'DATA รถถึงเส้นรอง KKN'!A:A) -> #N/A | E160: {=INDEX('DATA รถถึงเส้นรอง KKN'!C:C,ROW()-3)} -> 0 | F160: =_xlfn.XLOOKUP(E160,'DATA รถถึงเส้นรอง KKN'!C:C,'DATA รถถึงเส้นรอง KKN'!O:O) -> #N/A | G160: =_xlfn.XLOOKUP(E160,'DATA รถถึงเส้นรอง KKN'!C:C,'DATA รถถึงเส้นรอง KKN'!L:L) -> #N/A | H160: =_xlfn.XLOOKUP(E160,#REF!,#REF!) -> #REF! | I160: =_xlfn.XLOOKUP(E160,#REF!,#REF!) -> #REF! | J160: =_xlfn.XLOOKUP(E160,'DATA รถถึงเส้นรอง KKN'!C:C,'DATA รถถึงเส้นรอง KKN'!AP:AP) -> #N/A | K160: =_xlfn.XLOOKUP(E160,'DATA รถถึงเส้นรอง KKN'!C:C,'DATA รถถึงเส้นรอง KKN'!AV:AV) -> #N/A | L160: =M160+TIME(2,0,0) -> #N/A | M160: =_xlfn.XLOOKUP(E160,'DATA รถถึงเส้นรอง KKN'!C:C,'DATA รถถึงเส้นรอง KKN'!AW:AW) -> #N/A | N160: =_xlfn.XLOOKUP(E160,'DATA รถถึงเส้นรอง KKN'!C:C,'DATA รถถึงเส้นรอง KKN'!AY:AY) -> #N/A | O160: =IF(OR(N160=0,L160=0,N160="",L160=""),"ข้อมูลไม่ครบ",IF(TEXT(N160,"hh:mm:ss")>TEXT(L160,"hh:mm:ss"),"เกินเวลาลงพัสดุ","อยู่ในเวลาที่ควรลง")) -> #N/A | P160: =_xlfn.XLOOKUP(E160,'DATA รถถึงเส้นรอง KKN'!C:C,'DATA รถถึงเส้นรอง KKN'!AZ:AZ) -> #N/A | T160: =INT((V160-W160)*1440) -> #N/A | V160: =RIGHT(P160,8) -> #N/A | W160: =RIGHT(N160,8) -> #N/A | X160: =MOD(V160-W160,1) -> #N/A
B161: 157 | C161: =_xlfn.XLOOKUP(D:D,'DATA รถถึงเส้นรอง KKN'!A:A,'DATA รถถึงเส้นรอง KKN'!B:B) -> #N/A | D161: =_xlfn.XLOOKUP(E161,'DATA รถถึงเส้นรอง KKN'!C:C,'DATA รถถึงเส้นรอง KKN'!A:A) -> #N/A | E161: {=INDEX('DATA รถถึงเส้นรอง KKN'!C:C,ROW()-3)} -> 0 | F161: =_xlfn.XLOOKUP(E161,'DATA รถถึงเส้นรอง KKN'!C:C,'DATA รถถึงเส้นรอง KKN'!O:O) -> #N/A | G161: =_xlfn.XLOOKUP(E161,'DATA รถถึงเส้นรอง KKN'!C:C,'DATA รถถึงเส้นรอง KKN'!L:L) -> #N/A | H161: =_xlfn.XLOOKUP(E161,#REF!,#REF!) -> #REF! | I161: =_xlfn.XLOOKUP(E161,#REF!,#REF!) -> #REF! | J161: =_xlfn.XLOOKUP(E161,'DATA รถถึงเส้นรอง KKN'!C:C,'DATA รถถึงเส้นรอง KKN'!AP:AP) -> #N/A | K161: =_xlfn.XLOOKUP(E161,'DATA รถถึงเส้นรอง KKN'!C:C,'DATA รถถึงเส้นรอง KKN'!AV:AV) -> #N/A | L161: =M161+TIME(2,0,0) -> #N/A | M161: =_xlfn.XLOOKUP(E161,'DATA รถถึงเส้นรอง KKN'!C:C,'DATA รถถึงเส้นรอง KKN'!AW:AW) -> #N/A | N161: =_xlfn.XLOOKUP(E161,'DATA รถถึงเส้นรอง KKN'!C:C,'DATA รถถึงเส้นรอง KKN'!AY:AY) -> #N/A | O161: =IF(OR(N161=0,L161=0,N161="",L161=""),"ข้อมูลไม่ครบ",IF(TEXT(N161,"hh:mm:ss")>TEXT(L161,"hh:mm:ss"),"เกินเวลาลงพัสดุ","อยู่ในเวลาที่ควรลง")) -> #N/A | P161: =_xlfn.XLOOKUP(E161,'DATA รถถึงเส้นรอง KKN'!C:C,'DATA รถถึงเส้นรอง KKN'!AZ:AZ) -> #N/A | T161: =INT((V161-W161)*1440) -> #N/A | V161: =RIGHT(P161,8) -> #N/A | W161: =RIGHT(N161,8) -> #N/A | X161: =MOD(V161-W161,1) -> #N/A
B162: 158 | C162: =_xlfn.XLOOKUP(D:D,'DATA รถถึงเส้นรอง KKN'!A:A,'DATA รถถึงเส้นรอง KKN'!B:B) -> #N/A | D162: =_xlfn.XLOOKUP(E162,'DATA รถถึงเส้นรอง KKN'!C:C,'DATA รถถึงเส้นรอง KKN'!A:A) -> #N/A | E162: {=INDEX('DATA รถถึงเส้นรอง KKN'!C:C,ROW()-3)} -> 0 | F162: =_xlfn.XLOOKUP(E162,'DATA รถถึงเส้นรอง KKN'!C:C,'DATA รถถึงเส้นรอง KKN'!O:O) -> #N/A | G162: =_xlfn.XLOOKUP(E162,'DATA รถถึงเส้นรอง KKN'!C:C,'DATA รถถึงเส้นรอง KKN'!L:L) -> #N/A | H162: =_xlfn.XLOOKUP(E162,#REF!,#REF!) -> #REF! | I162: =_xlfn.XLOOKUP(E162,#REF!,#REF!) -> #REF! | J162: =_xlfn.XLOOKUP(E162,'DATA รถถึงเส้นรอง KKN'!C:C,'DATA รถถึงเส้นรอง KKN'!AP:AP) -> #N/A | K162: =_xlfn.XLOOKUP(E162,'DATA รถถึงเส้นรอง KKN'!C:C,'DATA รถถึงเส้นรอง KKN'!AV:AV) -> #N/A | L162: =M162+TIME(2,0,0) -> #N/A | M162: =_xlfn.XLOOKUP(E162,'DATA รถถึงเส้นรอง KKN'!C:C,'DATA รถถึงเส้นรอง KKN'!AW:AW) -> #N/A | N162: =_xlfn.XLOOKUP(E162,'DATA รถถึงเส้นรอง KKN'!C:C,'DATA รถถึงเส้นรอง KKN'!AY:AY) -> #N/A | O162: =IF(OR(N162=0,L162=0,N162="",L162=""),"ข้อมูลไม่ครบ",IF(TEXT(N162,"hh:mm:ss")>TEXT(L162,"hh:mm:ss"),"เกินเวลาลงพัสดุ","อยู่ในเวลาที่ควรลง")) -> #N/A | P162: =_xlfn.XLOOKUP(E162,'DATA รถถึงเส้นรอง KKN'!C:C,'DATA รถถึงเส้นรอง KKN'!AZ:AZ) -> #N/A | T162: =INT((V162-W162)*1440) -> #N/A | V162: =RIGHT(P162,8) -> #N/A | W162: =RIGHT(N162,8) -> #N/A | X162: =MOD(V162-W162,1) -> #N/A
B163: 159 | C163: =_xlfn.XLOOKUP(D:D,'DATA รถถึงเส้นรอง KKN'!A:A,'DATA รถถึงเส้นรอง KKN'!B:B) -> #N/A | D163: =_xlfn.XLOOKUP(E163,'DATA รถถึงเส้นรอง KKN'!C:C,'DATA รถถึงเส้นรอง KKN'!A:A) -> #N/A | E163: {=INDEX('DATA รถถึงเส้นรอง KKN'!C:C,ROW()-3)} -> 0 | F163: =_xlfn.XLOOKUP(E163,'DATA รถถึงเส้นรอง KKN'!C:C,'DATA รถถึงเส้นรอง KKN'!O:O) -> #N/A | G163: =_xlfn.XLOOKUP(E163,'DATA รถถึงเส้นรอง KKN'!C:C,'DATA รถถึงเส้นรอง KKN'!L:L) -> #N/A | H163: =_xlfn.XLOOKUP(E163,#REF!,#REF!) -> #REF! | I163: =_xlfn.XLOOKUP(E163,#REF!,#REF!) -> #REF! | J163: =_xlfn.XLOOKUP(E163,'DATA รถถึงเส้นรอง KKN'!C:C,'DATA รถถึงเส้นรอง KKN'!AP:AP) -> #N/A | K163: =_xlfn.XLOOKUP(E163,'DATA รถถึงเส้นรอง KKN'!C:C,'DATA รถถึงเส้นรอง KKN'!AV:AV) -> #N/A | L163: =M163+TIME(2,0,0) -> #N/A | M163: =_xlfn.XLOOKUP(E163,'DATA รถถึงเส้นรอง KKN'!C:C,'DATA รถถึงเส้นรอง KKN'!AW:AW) -> #N/A | N163: =_xlfn.XLOOKUP(E163,'DATA รถถึงเส้นรอง KKN'!C:C,'DATA รถถึงเส้นรอง KKN'!AY:AY) -> #N/A | O163: =IF(OR(N163=0,L163=0,N163="",L163=""),"ข้อมูลไม่ครบ",IF(TEXT(N163,"hh:mm:ss")>TEXT(L163,"hh:mm:ss"),"เกินเวลาลงพัสดุ","อยู่ในเวลาที่ควรลง")) -> #N/A | P163: =_xlfn.XLOOKUP(E163,'DATA รถถึงเส้นรอง KKN'!C:C,'DATA รถถึงเส้นรอง KKN'!AZ:AZ) -> #N/A | T163: =INT((V163-W163)*1440) -> #N/A | V163: =RIGHT(P163,8) -> #N/A | W163: =RIGHT(N163,8) -> #N/A | X163: =MOD(V163-W163,1) -> #N/A
B164: 160 | C164: =_xlfn.XLOOKUP(D:D,'DATA รถถึงเส้นรอง KKN'!A:A,'DATA รถถึงเส้นรอง KKN'!B:B) -> #N/A | D164: =_xlfn.XLOOKUP(E164,'DATA รถถึงเส้นรอง KKN'!C:C,'DATA รถถึงเส้นรอง KKN'!A:A) -> #N/A | E164: {=INDEX('DATA รถถึงเส้นรอง KKN'!C:C,ROW()-3)} -> 0 | F164: =_xlfn.XLOOKUP(E164,'DATA รถถึงเส้นรอง KKN'!C:C,'DATA รถถึงเส้นรอง KKN'!O:O) -> #N/A | G164: =_xlfn.XLOOKUP(E164,'DATA รถถึงเส้นรอง KKN'!C:C,'DATA รถถึงเส้นรอง KKN'!L:L) -> #N/A | H164: =_xlfn.XLOOKUP(E164,#REF!,#REF!) -> #REF! | I164: =_xlfn.XLOOKUP(E164,#REF!,#REF!) -> #REF! | J164: =_xlfn.XLOOKUP(E164,'DATA รถถึงเส้นรอง KKN'!C:C,'DATA รถถึงเส้นรอง KKN'!AP:AP) -> #N/A | K164: =_xlfn.XLOOKUP(E164,'DATA รถถึงเส้นรอง KKN'!C:C,'DATA รถถึงเส้นรอง KKN'!AV:AV) -> #N/A | L164: =M164+TIME(2,0,0) -> #N/A | M164: =_xlfn.XLOOKUP(E164,'DATA รถถึงเส้นรอง KKN'!C:C,'DATA รถถึงเส้นรอง KKN'!AW:AW) -> #N/A | N164: =_xlfn.XLOOKUP(E164,'DATA รถถึงเส้นรอง KKN'!C:C,'DATA รถถึงเส้นรอง KKN'!AY:AY) -> #N/A | O164: =IF(OR(N164=0,L164=0,N164="",L164=""),"ข้อมูลไม่ครบ",IF(TEXT(N164,"hh:mm:ss")>TEXT(L164,"hh:mm:ss"),"เกินเวลาลงพัสดุ","อยู่ในเวลาที่ควรลง")) -> #N/A | P164: =_xlfn.XLOOKUP(E164,'DATA รถถึงเส้นรอง KKN'!C:C,'DATA รถถึงเส้นรอง KKN'!AZ:AZ) -> #N/A | T164: =INT((V164-W164)*1440) -> #N/A | V164: =RIGHT(P164,8) -> #N/A | W164: =RIGHT(N164,8) -> #N/A | X164: =MOD(V164-W164,1) -> #N/A
B165: 161 | C165: =_xlfn.XLOOKUP(D:D,'DATA รถถึงเส้นรอง KKN'!A:A,'DATA รถถึงเส้นรอง KKN'!B:B) -> #N/A | D165: =_xlfn.XLOOKUP(E165,'DATA รถถึงเส้นรอง KKN'!C:C,'DATA รถถึงเส้นรอง KKN'!A:A) -> #N/A | E165: {=INDEX('DATA รถถึงเส้นรอง KKN'!C:C,ROW()-3)} -> 0 | F165: =_xlfn.XLOOKUP(E165,'DATA รถถึงเส้นรอง KKN'!C:C,'DATA รถถึงเส้นรอง KKN'!O:O) -> #N/A | G165: =_xlfn.XLOOKUP(E165,'DATA รถถึงเส้นรอง KKN'!C:C,'DATA รถถึงเส้นรอง KKN'!L:L) -> #N/A | H165: =_xlfn.XLOOKUP(E165,#REF!,#REF!) -> #REF! | I165: =_xlfn.XLOOKUP(E165,#REF!,#REF!) -> #REF! | J165: =_xlfn.XLOOKUP(E165,'DATA รถถึงเส้นรอง KKN'!C:C,'DATA รถถึงเส้นรอง KKN'!AP:AP) -> #N/A | K165: =_xlfn.XLOOKUP(E165,'DATA รถถึงเส้นรอง KKN'!C:C,'DATA รถถึงเส้นรอง KKN'!AV:AV) -> #N/A | L165: =M165+TIME(2,0,0) -> #N/A | M165: =_xlfn.XLOOKUP(E165,'DATA รถถึงเส้นรอง KKN'!C:C,'DATA รถถึงเส้นรอง KKN'!AW:AW) -> #N/A | N165: =_xlfn.XLOOKUP(E165,'DATA รถถึงเส้นรอง KKN'!C:C,'DATA รถถึงเส้นรอง KKN'!AY:AY) -> #N/A | O165: =IF(OR(N165=0,L165=0,N165="",L165=""),"ข้อมูลไม่ครบ",IF(TEXT(N165,"hh:mm:ss")>TEXT(L165,"hh:mm:ss"),"เกินเวลาลงพัสดุ","อยู่ในเวลาที่ควรลง")) -> #N/A | P165: =_xlfn.XLOOKUP(E165,'DATA รถถึงเส้นรอง KKN'!C:C,'DATA รถถึงเส้นรอง KKN'!AZ:AZ) -> #N/A | T165: =INT((V165-W165)*1440) -> #N/A | V165: =RIGHT(P165,8) -> #N/A | W165: =RIGHT(N165,8) -> #N/A | X165: =MOD(V165-W165,1) -> #N/A
B166: 162 | C166: =_xlfn.XLOOKUP(D:D,'DATA รถถึงเส้นรอง KKN'!A:A,'DATA รถถึงเส้นรอง KKN'!B:B) -> #N/A | D166: =_xlfn.XLOOKUP(E166,'DATA รถถึงเส้นรอง KKN'!C:C,'DATA รถถึงเส้นรอง KKN'!A:A) -> #N/A | E166: {=INDEX('DATA รถถึงเส้นรอง KKN'!C:C,ROW()-3)} -> 0 | F166: =_xlfn.XLOOKUP(E166,'DATA รถถึงเส้นรอง KKN'!C:C,'DATA รถถึงเส้นรอง KKN'!O:O) -> #N/A | G166: =_xlfn.XLOOKUP(E166,'DATA รถถึงเส้นรอง KKN'!C:C,'DATA รถถึงเส้นรอง KKN'!L:L) -> #N/A | H166: =_xlfn.XLOOKUP(E166,#REF!,#REF!) -> #REF! | I166: =_xlfn.XLOOKUP(E166,#REF!,#REF!) -> #REF! | J166: =_xlfn.XLOOKUP(E166,'DATA รถถึงเส้นรอง KKN'!C:C,'DATA รถถึงเส้นรอง KKN'!AP:AP) -> #N/A | K166: =_xlfn.XLOOKUP(E166,'DATA รถถึงเส้นรอง KKN'!C:C,'DATA รถถึงเส้นรอง KKN'!AV:AV) -> #N/A | L166: =M166+TIME(2,0,0) -> #N/A | M166: =_xlfn.XLOOKUP(E166,'DATA รถถึงเส้นรอง KKN'!C:C,'DATA รถถึงเส้นรอง KKN'!AW:AW) -> #N/A | N166: =_xlfn.XLOOKUP(E166,'DATA รถถึงเส้นรอง KKN'!C:C,'DATA รถถึงเส้นรอง KKN'!AY:AY) -> #N/A | O166: =IF(OR(N166=0,L166=0,N166="",L166=""),"ข้อมูลไม่ครบ",IF(TEXT(N166,"hh:mm:ss")>TEXT(L166,"hh:mm:ss"),"เกินเวลาลงพัสดุ","อยู่ในเวลาที่ควรลง")) -> #N/A | P166: =_xlfn.XLOOKUP(E166,'DATA รถถึงเส้นรอง KKN'!C:C,'DATA รถถึงเส้นรอง KKN'!AZ:AZ) -> #N/A | T166: =INT((V166-W166)*1440) -> #N/A | V166: =RIGHT(P166,8) -> #N/A | W166: =RIGHT(N166,8) -> #N/A | X166: =MOD(V166-W166,1) -> #N/A
B167: 163 | C167: =_xlfn.XLOOKUP(D:D,'DATA รถถึงเส้นรอง KKN'!A:A,'DATA รถถึงเส้นรอง KKN'!B:B) -> #N/A | D167: =_xlfn.XLOOKUP(E167,'DATA รถถึงเส้นรอง KKN'!C:C,'DATA รถถึงเส้นรอง KKN'!A:A) -> #N/A | E167: {=INDEX('DATA รถถึงเส้นรอง KKN'!C:C,ROW()-3)} -> 0 | F167: =_xlfn.XLOOKUP(E167,'DATA รถถึงเส้นรอง KKN'!C:C,'DATA รถถึงเส้นรอง KKN'!O:O) -> #N/A | G167: =_xlfn.XLOOKUP(E167,'DATA รถถึงเส้นรอง KKN'!C:C,'DATA รถถึงเส้นรอง KKN'!L:L) -> #N/A | H167: =_xlfn.XLOOKUP(E167,#REF!,#REF!) -> #REF! | I167: =_xlfn.XLOOKUP(E167,#REF!,#REF!) -> #REF! | J167: =_xlfn.XLOOKUP(E167,'DATA รถถึงเส้นรอง KKN'!C:C,'DATA รถถึงเส้นรอง KKN'!AP:AP) -> #N/A | K167: =_xlfn.XLOOKUP(E167,'DATA รถถึงเส้นรอง KKN'!C:C,'DATA รถถึงเส้นรอง KKN'!AV:AV) -> #N/A | L167: =M167+TIME(2,0,0) -> #N/A | M167: =_xlfn.XLOOKUP(E167,'DATA รถถึงเส้นรอง KKN'!C:C,'DATA รถถึงเส้นรอง KKN'!AW:AW) -> #N/A | N167: =_xlfn.XLOOKUP(E167,'DATA รถถึงเส้นรอง KKN'!C:C,'DATA รถถึงเส้นรอง KKN'!AY:AY) -> #N/A | O167: =IF(OR(N167=0,L167=0,N167="",L167=""),"ข้อมูลไม่ครบ",IF(TEXT(N167,"hh:mm:ss")>TEXT(L167,"hh:mm:ss"),"เกินเวลาลงพัสดุ","อยู่ในเวลาที่ควรลง")) -> #N/A | P167: =_xlfn.XLOOKUP(E167,'DATA รถถึงเส้นรอง KKN'!C:C,'DATA รถถึงเส้นรอง KKN'!AZ:AZ) -> #N/A | T167: =INT((V167-W167)*1440) -> #N/A | V167: =RIGHT(P167,8) -> #N/A | W167: =RIGHT(N167,8) -> #N/A | X167: =MOD(V167-W167,1) -> #N/A
B168: 164 | C168: =_xlfn.XLOOKUP(D:D,'DATA รถถึงเส้นรอง KKN'!A:A,'DATA รถถึงเส้นรอง KKN'!B:B) -> #N/A | D168: =_xlfn.XLOOKUP(E168,'DATA รถถึงเส้นรอง KKN'!C:C,'DATA รถถึงเส้นรอง KKN'!A:A) -> #N/A | E168: {=INDEX('DATA รถถึงเส้นรอง KKN'!C:C,ROW()-3)} -> 0 | F168: =_xlfn.XLOOKUP(E168,'DATA รถถึงเส้นรอง KKN'!C:C,'DATA รถถึงเส้นรอง KKN'!O:O) -> #N/A | G168: =_xlfn.XLOOKUP(E168,'DATA รถถึงเส้นรอง KKN'!C:C,'DATA รถถึงเส้นรอง KKN'!L:L) -> #N/A | H168: =_xlfn.XLOOKUP(E168,#REF!,#REF!) -> #REF! | I168: =_xlfn.XLOOKUP(E168,#REF!,#REF!) -> #REF! | J168: =_xlfn.XLOOKUP(E168,'DATA รถถึงเส้นรอง KKN'!C:C,'DATA รถถึงเส้นรอง KKN'!AP:AP) -> #N/A | K168: =_xlfn.XLOOKUP(E168,'DATA รถถึงเส้นรอง KKN'!C:C,'DATA รถถึงเส้นรอง KKN'!AV:AV) -> #N/A | L168: =M168+TIME(2,0,0) -> #N/A | M168: =_xlfn.XLOOKUP(E168,'DATA รถถึงเส้นรอง KKN'!C:C,'DATA รถถึงเส้นรอง KKN'!AW:AW) -> #N/A | N168: =_xlfn.XLOOKUP(E168,'DATA รถถึงเส้นรอง KKN'!C:C,'DATA รถถึงเส้นรอง KKN'!AY:AY) -> #N/A | O168: =IF(OR(N168=0,L168=0,N168="",L168=""),"ข้อมูลไม่ครบ",IF(TEXT(N168,"hh:mm:ss")>TEXT(L168,"hh:mm:ss"),"เกินเวลาลงพัสดุ","อยู่ในเวลาที่ควรลง")) -> #N/A | P168: =_xlfn.XLOOKUP(E168,'DATA รถถึงเส้นรอง KKN'!C:C,'DATA รถถึงเส้นรอง KKN'!AZ:AZ) -> #N/A | T168: =INT((V168-W168)*1440) -> #N/A | V168: =RIGHT(P168,8) -> #N/A | W168: =RIGHT(N168,8) -> #N/A | X168: =MOD(V168-W168,1) -> #N/A
B169: 165 | C169: =_xlfn.XLOOKUP(D:D,'DATA รถถึงเส้นรอง KKN'!A:A,'DATA รถถึงเส้นรอง KKN'!B:B) -> #N/A | D169: =_xlfn.XLOOKUP(E169,'DATA รถถึงเส้นรอง KKN'!C:C,'DATA รถถึงเส้นรอง KKN'!A:A) -> #N/A | E169: {=INDEX('DATA รถถึงเส้นรอง KKN'!C:C,ROW()-3)} -> 0 | F169: =_xlfn.XLOOKUP(E169,'DATA รถถึงเส้นรอง KKN'!C:C,'DATA รถถึงเส้นรอง KKN'!O:O) -> #N/A | G169: =_xlfn.XLOOKUP(E169,'DATA รถถึงเส้นรอง KKN'!C:C,'DATA รถถึงเส้นรอง KKN'!L:L) -> #N/A | H169: =_xlfn.XLOOKUP(E169,#REF!,#REF!) -> #REF! | I169: =_xlfn.XLOOKUP(E169,#REF!,#REF!) -> #REF! | J169: =_xlfn.XLOOKUP(E169,'DATA รถถึงเส้นรอง KKN'!C:C,'DATA รถถึงเส้นรอง KKN'!AP:AP) -> #N/A | K169: =_xlfn.XLOOKUP(E169,'DATA รถถึงเส้นรอง KKN'!C:C,'DATA รถถึงเส้นรอง KKN'!AV:AV) -> #N/A | L169: =M169+TIME(2,0,0) -> #N/A | M169: =_xlfn.XLOOKUP(E169,'DATA รถถึงเส้นรอง KKN'!C:C,'DATA รถถึงเส้นรอง KKN'!AW:AW) -> #N/A | N169: =_xlfn.XLOOKUP(E169,'DATA รถถึงเส้นรอง KKN'!C:C,'DATA รถถึงเส้นรอง KKN'!AY:AY) -> #N/A | O169: =IF(OR(N169=0,L169=0,N169="",L169=""),"ข้อมูลไม่ครบ",IF(TEXT(N169,"hh:mm:ss")>TEXT(L169,"hh:mm:ss"),"เกินเวลาลงพัสดุ","อยู่ในเวลาที่ควรลง")) -> #N/A | P169: =_xlfn.XLOOKUP(E169,'DATA รถถึงเส้นรอง KKN'!C:C,'DATA รถถึงเส้นรอง KKN'!AZ:AZ) -> #N/A | T169: =INT((V169-W169)*1440) -> #N/A | V169: =RIGHT(P169,8) -> #N/A | W169: =RIGHT(N169,8) -> #N/A | X169: =MOD(V169-W169,1) -> #N/A
... B179: 175 | C179: =_xlfn.XLOOKUP(D:D,'DATA รถถึงเส้นรอง KKN'!A:A,'DATA รถถึงเส้นรอง KKN'!B:B) -> #N/A | D179: =_xlfn.XLOOKUP(E179,'DATA รถถึงเส้นรอง KKN'!C:C,'DATA รถถึงเส้นรอง KKN'!A:A) -> #N/A | E179: {=INDEX('DATA รถถึงเส้นรอง KKN'!C:C,ROW()-3)} -> 0 | F179: =_xlfn.XLOOKUP(E179,'DATA รถถึงเส้นรอง KKN'!C:C,'DATA รถถึงเส้นรอง KKN'!O:O) -> #N/A | G179: =_xlfn.XLOOKUP(E179,'DATA รถถึงเส้นรอง KKN'!C:C,'DATA รถถึงเส้นรอง KKN'!L:L) -> #N/A | H179: =_xlfn.XLOOKUP(E179,#REF!,#REF!) -> #REF! | I179: =_xlfn.XLOOKUP(E179,#REF!,#REF!) -> #REF! | J179: =_xlfn.XLOOKUP(E179,'DATA รถถึงเส้นรอง KKN'!C:C,'DATA รถถึงเส้นรอง KKN'!AP:AP) -> #N/A | K179: =_xlfn.XLOOKUP(E179,'DATA รถถึงเส้นรอง KKN'!C:C,'DATA รถถึงเส้นรอง KKN'!AV:AV) -> #N/A | L179: =M179+TIME(2,0,0) -> #N/A | M179: =_xlfn.XLOOKUP(E179,'DATA รถถึงเส้นรอง KKN'!C:C,'DATA รถถึงเส้นรอง KKN'!AW:AW) -> #N/A | N179: =_xlfn.XLOOKUP(E179,'DATA รถถึงเส้นรอง KKN'!C:C,'DATA รถถึงเส้นรอง KKN'!AY:AY) -> #N/A | O179: =IF(OR(N179=0,L179=0,N179="",L179=""),"ข้อมูลไม่ครบ",IF(TEXT(N179,"hh:mm:ss")>TEXT(L179,"hh:mm:ss"),"เกินเวลาลงพัสดุ","อยู่ในเวลาที่ควรลง")) -> #N/A | P179: =_xlfn.XLOOKUP(E179,'DATA รถถึงเส้นรอง KKN'!C:C,'DATA รถถึงเส้นรอง KKN'!AZ:AZ) -> #N/A | T179: =INT((V179-W179)*1440) -> #N/A | V179: =RIGHT(P179,8) -> #N/A | W179: =RIGHT(N179,8) -> #N/A | X179: =MOD(V179-W179,1) -> #N/A
B180: 加班车 รถเสริม
B181: 序号 | C181: 任务状态 | D181: 任务单 | E181: 路线 | F181: 车辆类型 | G181: 车牌号 | H181: 司机名称 | I181: 供应商 | J181: เวลามาถึงโดยประมาณ | K181: 实际到车时间 เวลารถถึง | L181: เวลาที่ควรลง (ไม่เกิน2hr.) | M181: 解车时间 | N181: 卸车开始时间 | O181: สถานะความผิดปกติ | P181: 卸车结束时间 | Q181: 卸车状态 | R181: 备注 | T181: เกินระยะเวลาลงงาน
B182: NO. | C182: สถานะ | D182: เลขมอบหมายงาน | E182: รอบรถ | F182: ประเภทรถ | G182: ทะเบียน | H182: ชื่อคนขับ | I182: ซัพพลายเออร์ | M182: เวลาเปิดตู้รถถึง | N182: เวลาเริ่มลงพัสดุ | P182: เวลาสิ้นสุดลงพัสดุ | Q182: สถานะลงของ | R182: หมายเหตุ
B183: 1 | C183: =_xlfn.XLOOKUP(D:D,#REF!,#REF!) -> #REF! | F183: =_xlfn.XLOOKUP(E183,#REF!,#REF!) -> #REF! | G183: =_xlfn.XLOOKUP(E183,#REF!,#REF!) -> #REF! | H183: =_xlfn.XLOOKUP(E183,#REF!,#REF!) -> #REF! | I183: =_xlfn.XLOOKUP(E183,#REF!,#REF!) -> #REF! | J183: =_xlfn.XLOOKUP(E183,#REF!,#REF!) -> #REF! | K183: =_xlfn.XLOOKUP(E183,#REF!,#REF!) -> #REF! | L183: =M183+TIME(2,0,0) -> #REF! | M183: =_xlfn.XLOOKUP(E183,#REF!,#REF!) -> #REF! | N183: =_xlfn.XLOOKUP(E183,#REF!,#REF!) -> #REF! | O183: =IF(OR(N183=0,L183=0,N183="",L183=""),"ข้อมูลไม่ครบ",IF(TEXT(N183,"hh:mm:ss")>TEXT(L183,"hh:mm:ss"),"เกินเวลาลงพัสดุ","อยู่ในเวลาที่ควรลง")) -> #REF! | P183: =_xlfn.XLOOKUP(E183,#REF!,#REF!) -> #REF! | T183: =_xlfn.XLOOKUP(E183,#REF!,#REF!) -> #REF! | V183: =RIGHT(P183,8) -> #REF! | W183: =RIGHT(N183,8) -> #REF! | X183: =MOD(V183-W183,1) -> #REF!
B184: 2 | C184: =_xlfn.XLOOKUP(D:D,#REF!,#REF!) -> #REF! | F184: =_xlfn.XLOOKUP(E184,#REF!,#REF!) -> #REF! | G184: =_xlfn.XLOOKUP(E184,#REF!,#REF!) -> #REF! | H184: =_xlfn.XLOOKUP(E184,#REF!,#REF!) -> #REF! | I184: =_xlfn.XLOOKUP(E184,#REF!,#REF!) -> #REF! | J184: =_xlfn.XLOOKUP(E184,#REF!,#REF!) -> #REF! | K184: =_xlfn.XLOOKUP(E184,#REF!,#REF!) -> #REF! | L184: =M184+TIME(2,0,0) -> #REF! | M184: =_xlfn.XLOOKUP(E184,#REF!,#REF!) -> #REF! | N184: =_xlfn.XLOOKUP(E184,#REF!,#REF!) -> #REF! | O184: =IF(OR(N184=0,L184=0,N184="",L184=""),"ข้อมูลไม่ครบ",IF(TEXT(N184,"hh:mm:ss")>TEXT(L184,"hh:mm:ss"),"เกินเวลาลงพัสดุ","อยู่ในเวลาที่ควรลง")) -> #REF! | P184: =_xlfn.XLOOKUP(E184,#REF!,#REF!) -> #REF! | T184: =_xlfn.XLOOKUP(E184,#REF!,#REF!) -> #REF! | V184: =RIGHT(P184,8) -> #REF! | W184: =RIGHT(N184,8) -> #REF! | X184: =MOD(V184-W184,1) -> #REF!
B185: 3 | C185: =_xlfn.XLOOKUP(D:D,#REF!,#REF!) -> #REF! | F185: =_xlfn.XLOOKUP(E185,#REF!,#REF!) -> #REF! | G185: =_xlfn.XLOOKUP(E185,#REF!,#REF!) -> #REF! | H185: =_xlfn.XLOOKUP(E185,#REF!,#REF!) -> #REF! | I185: =_xlfn.XLOOKUP(E185,#REF!,#REF!) -> #REF! | J185: =_xlfn.XLOOKUP(E185,#REF!,#REF!) -> #REF! | K185: =_xlfn.XLOOKUP(E185,#REF!,#REF!) -> #REF! | L185: =M185+TIME(2,0,0) -> #REF! | M185: =_xlfn.XLOOKUP(E185,#REF!,#REF!) -> #REF! | N185: =_xlfn.XLOOKUP(E185,#REF!,#REF!) -> #REF! | O185: =IF(OR(N185=0,L185=0,N185="",L185=""),"ข้อมูลไม่ครบ",IF(TEXT(N185,"hh:mm:ss")>TEXT(L185,"hh:mm:ss"),"เกินเวลาลงพัสดุ","อยู่ในเวลาที่ควรลง")) -> #REF! | P185: =_xlfn.XLOOKUP(E185,#REF!,#REF!) -> #REF! | T185: =_xlfn.XLOOKUP(E185,#REF!,#REF!) -> #REF! | V185: =RIGHT(P185,8) -> #REF! | W185: =RIGHT(N185,8) -> #REF! | X185: =MOD(V185-W185,1) -> #REF!
B186: 4 | C186: =_xlfn.XLOOKUP(D:D,#REF!,#REF!) -> #REF! | F186: =_xlfn.XLOOKUP(E186,#REF!,#REF!) -> #REF! | G186: =_xlfn.XLOOKUP(E186,#REF!,#REF!) -> #REF! | H186: =_xlfn.XLOOKUP(E186,#REF!,#REF!) -> #REF! | I186: =_xlfn.XLOOKUP(E186,#REF!,#REF!) -> #REF! | J186: =_xlfn.XLOOKUP(E186,#REF!,#REF!) -> #REF! | K186: =_xlfn.XLOOKUP(E186,#REF!,#REF!) -> #REF! | L186: =M186+TIME(2,0,0) -> #REF! | M186: =_xlfn.XLOOKUP(E186,#REF!,#REF!) -> #REF! | N186: =_xlfn.XLOOKUP(E186,#REF!,#REF!) -> #REF! | O186: =IF(OR(N186=0,L186=0,N186="",L186=""),"ข้อมูลไม่ครบ",IF(TEXT(N186,"hh:mm:ss")>TEXT(L186,"hh:mm:ss"),"เกินเวลาลงพัสดุ","อยู่ในเวลาที่ควรลง")) -> #REF! | P186: =_xlfn.XLOOKUP(E186,#REF!,#REF!) -> #REF! | T186: =_xlfn.XLOOKUP(E186,#REF!,#REF!) -> #REF! | V186: =RIGHT(P186,8) -> #REF! | W186: =RIGHT(N186,8) -> #REF! | X186: =MOD(V186-W186,1) -> #REF!
B187: 5 | C187: =_xlfn.XLOOKUP(D:D,#REF!,#REF!) -> #REF! | F187: =_xlfn.XLOOKUP(E187,#REF!,#REF!) -> #REF! | G187: =_xlfn.XLOOKUP(E187,#REF!,#REF!) -> #REF! | H187: =_xlfn.XLOOKUP(E187,#REF!,#REF!) -> #REF! | I187: =_xlfn.XLOOKUP(E187,#REF!,#REF!) -> #REF! | J187: =_xlfn.XLOOKUP(E187,#REF!,#REF!) -> #REF! | K187: =_xlfn.XLOOKUP(E187,#REF!,#REF!) -> #REF! | L187: =M187+TIME(2,0,0) -> #REF! | M187: =_xlfn.XLOOKUP(E187,#REF!,#REF!) -> #REF! | N187: =_xlfn.XLOOKUP(E187,#REF!,#REF!) -> #REF! | O187: =IF(OR(N187=0,L187=0,N187="",L187=""),"ข้อมูลไม่ครบ",IF(TEXT(N187,"hh:mm:ss")>TEXT(L187,"hh:mm:ss"),"เกินเวลาลงพัสดุ","อยู่ในเวลาที่ควรลง")) -> #REF! | P187: =_xlfn.XLOOKUP(E187,#REF!,#REF!) -> #REF! | T187: =_xlfn.XLOOKUP(E187,#REF!,#REF!) -> #REF! | V187: =RIGHT(P187,8) -> #REF! | W187: =RIGHT(N187,8) -> #REF! | X187: =MOD(V187-W187,1) -> #REF!
B188: 6 | C188: =_xlfn.XLOOKUP(D:D,#REF!,#REF!) -> #REF! | F188: =_xlfn.XLOOKUP(E188,#REF!,#REF!) -> #REF! | G188: =_xlfn.XLOOKUP(E188,#REF!,#REF!) -> #REF! | H188: =_xlfn.XLOOKUP(E188,#REF!,#REF!) -> #REF! | I188: =_xlfn.XLOOKUP(E188,#REF!,#REF!) -> #REF! | J188: =_xlfn.XLOOKUP(E188,#REF!,#REF!) -> #REF! | K188: =_xlfn.XLOOKUP(E188,#REF!,#REF!) -> #REF! | L188: =M188+TIME(2,0,0) -> #REF! | M188: =_xlfn.XLOOKUP(E188,#REF!,#REF!) -> #REF! | N188: =_xlfn.XLOOKUP(E188,#REF!,#REF!) -> #REF! | O188: =IF(OR(N188=0,L188=0,N188="",L188=""),"ข้อมูลไม่ครบ",IF(TEXT(N188,"hh:mm:ss")>TEXT(L188,"hh:mm:ss"),"เกินเวลาลงพัสดุ","อยู่ในเวลาที่ควรลง")) -> #REF! | P188: =_xlfn.XLOOKUP(E188,#REF!,#REF!) -> #REF! | T188: =_xlfn.XLOOKUP(E188,#REF!,#REF!) -> #REF! | V188: =RIGHT(P188,8) -> #REF! | W188: =RIGHT(N188,8) -> #REF! | X188: =MOD(V188-W188,1) -> #REF!
B189: 7 | C189: =_xlfn.XLOOKUP(D:D,#REF!,#REF!) -> #REF! | F189: =_xlfn.XLOOKUP(E189,#REF!,#REF!) -> #REF! | G189: =_xlfn.XLOOKUP(E189,#REF!,#REF!) -> #REF! | H189: =_xlfn.XLOOKUP(E189,#REF!,#REF!) -> #REF! | I189: =_xlfn.XLOOKUP(E189,#REF!,#REF!) -> #REF! | J189: =_xlfn.XLOOKUP(E189,#REF!,#REF!) -> #REF! | K189: =_xlfn.XLOOKUP(E189,#REF!,#REF!) -> #REF! | L189: =M189+TIME(2,0,0) -> #REF! | M189: =_xlfn.XLOOKUP(E189,#REF!,#REF!) -> #REF! | N189: =_xlfn.XLOOKUP(E189,#REF!,#REF!) -> #REF! | O189: =IF(OR(N189=0,L189=0,N189="",L189=""),"ข้อมูลไม่ครบ",IF(TEXT(N189,"hh:mm:ss")>TEXT(L189,"hh:mm:ss"),"เกินเวลาลงพัสดุ","อยู่ในเวลาที่ควรลง")) -> #REF! | P189: =_xlfn.XLOOKUP(E189,#REF!,#REF!) -> #REF! | T189: =_xlfn.XLOOKUP(E189,#REF!,#REF!) -> #REF! | V189: =RIGHT(P189,8) -> #REF! | W189: =RIGHT(N189,8) -> #REF! | X189: =MOD(V189-W189,1) -> #REF!
B190: 8 | C190: =_xlfn.XLOOKUP(D:D,#REF!,#REF!) -> #REF! | F190: =_xlfn.XLOOKUP(E190,#REF!,#REF!) -> #REF! | G190: =_xlfn.XLOOKUP(E190,#REF!,#REF!) -> #REF! | H190: =_xlfn.XLOOKUP(E190,#REF!,#REF!) -> #REF! | I190: =_xlfn.XLOOKUP(E190,#REF!,#REF!) -> #REF! | J190: =_xlfn.XLOOKUP(E190,#REF!,#REF!) -> #REF! | K190: =_xlfn.XLOOKUP(E190,#REF!,#REF!) -> #REF! | L190: =M190+TIME(2,0,0) -> #REF! | M190: =_xlfn.XLOOKUP(E190,#REF!,#REF!) -> #REF! | N190: =_xlfn.XLOOKUP(E190,#REF!,#REF!) -> #REF! | O190: =IF(OR(N190=0,L190=0,N190="",L190=""),"ข้อมูลไม่ครบ",IF(TEXT(N190,"hh:mm:ss")>TEXT(L190,"hh:mm:ss"),"เกินเวลาลงพัสดุ","อยู่ในเวลาที่ควรลง")) -> #REF! | P190: =_xlfn.XLOOKUP(E190,#REF!,#REF!) -> #REF! | T190: =_xlfn.XLOOKUP(E190,#REF!,#REF!) -> #REF! | V190: =RIGHT(P190,8) -> #REF! | W190: =RIGHT(N190,8) -> #REF! | X190: =MOD(V190-W190,1) -> #REF!
...

Sheet DATA รถถึงเส้นรอง KKN
A1: หมายเลขใบงาน | B1: สถานะการทำงาน | C1: ชื่อใบสั่งงาน | D1: ชื่อสถานที่ของเส้นทาง | E1: ชื่อสถานที่ของเส้นทางที่อ้างอิง | F1: 发车场地名称 | G1: 到车场地名称 | H1: ประเภทงาน | I1: ประเภทเส้นทาง | J1: กะการทำงาน | K1: ระยะทางไมล์ | L1: หมายเลขทะเบียนรถ | M1: ทะเบียนรถ/จังหวัด | N1: ทะเบียนรถพ่วง/จังหวัด | O1: ประเภทรถ | P1: ชื่อเต็มซัพพลายเออร์ | Q1: ชื่อคนขับรถ | R1: เบอร์โทร | S1: รหัสสาขาต้นทาง | T1: ชื่อ DP ที่ปล่อยรถ | U1: แฟรนไชส์ปล่อยรถ | V1: RGMปล่อยรถ | W1: จังหวัดต้นทาง | X1: เวลาเริ่มการโหลดบรรจุขึ้นรถ | Y1: เวลาสิ้นสุดในการโหลดบรรจุขึ้นรถ | Z1: ระยะเวลาขนถ่ายขึ้นรถ(min） | AA1: 装车是否超过20H | AB1: เวลาปิดรถ | AC1: เวลาที่คาดว่าจะปล่อยรถ | AD1: เวลารอปล่อยรถ | AE1: เวลารับสินค้า | AF1: เวลาปล่อยรถตามจริง | AG1: ระยะเวลาปล่อยรถล่าช้า | AH1: ปล่อยรถล่าช้า | AI1: เวลานำส่งขนถ่ายขึ้นรถ | AJ1: เวลาเช็คเอาต์คนขับ | AK1: รหัสสาขาปลายทาง | AL1: ชื่อDPที่รถมาถึง | AM1: แฟรนไชส์รถถึง | AN1: RGMรถถึง | AO1: จังหวัดที่รถมาถึง | AP1: เวลาที่คาดว่ารถจะถึง | AQ1: เวลาที่ถึงจริง | AR1: ระยะเวลาล่าช้า(นาที) | AS1: รถถึงเลท | AT1: เวลาขนส่งล่าช้า(ชม.) | AU1: 运行是否晚点 | AV1: เวลาเข้างานของคนขับ | AW1: เวลาคัดแยกรถ | AX1: รายะเวลาเข้าแถวขนถ่ายลงรถ(min） | AY1: ระยะเวลาเริ่มงานที่ใช้ขนย้ายลงรถ | AZ1: ระยะเวลาจบงานที่ใช้ขนย้ายลงรถ | BA1: ระยะเวลาขนถ่ายลงรถ(min）

Sheet วิธีการดึง
C3: 1.รถถึงสายรอง วิธีดึง
C26: 2.ส่งออกข้อมูล
